WARNING:root:Path Error;
WARNING:root:Path Error;
ERROR:root:Internal Python error in the inspect module.
Below is the traceback from this internal error.

INFO:root:
Unfortunately, your original traceback can not be constructed.

WARNING:root:Error Date: 2019-07-31 00:00:00
ERROR:sqlalchemy.pool.QueuePool:Exception during reset or similar
Traceback (most recent call last):
  File "/home/chengtong/anaconda3/lib/python3.6/site-packages/sqlalchemy/engine/base.py", line 1193, in _execute_context
    context)
  File "/home/chengtong/anaconda3/lib/python3.6/site-packages/sqlalchemy/engine/default.py", line 507, in do_execute
    cursor.execute(statement, parameters)
  File "/home/chengtong/anaconda3/lib/python3.6/site-packages/pymysql/cursors.py", line 170, in execute
    result = self._query(query)
  File "/home/chengtong/anaconda3/lib/python3.6/site-packages/pymysql/cursors.py", line 328, in _query
    conn.query(q)
  File "/home/chengtong/anaconda3/lib/python3.6/site-packages/pymysql/connections.py", line 517, in query
    self._affected_rows = self._read_query_result(unbuffered=unbuffered)
  File "/home/chengtong/anaconda3/lib/python3.6/site-packages/pymysql/connections.py", line 732, in _read_query_result
    result.read()
  File "/home/chengtong/anaconda3/lib/python3.6/site-packages/pymysql/connections.py", line 1082, in read
    self._read_result_packet(first_packet)
  File "/home/chengtong/anaconda3/lib/python3.6/site-packages/pymysql/connections.py", line 1152, in _read_result_packet
    self._read_rowdata_packet()
  File "/home/chengtong/anaconda3/lib/python3.6/site-packages/pymysql/connections.py", line 1190, in _read_rowdata_packet
    rows.append(self._read_row_from_packet(packet))
  File "/home/chengtong/anaconda3/lib/python3.6/site-packages/pymysql/connections.py", line 1199, in _read_row_from_packet
    data = packet.read_length_coded_string()
  File "/home/chengtong/anaconda3/lib/python3.6/site-packages/pymysql/protocol.py", line 178, in read_length_coded_string
    return self.read(length)
  File "/home/chengtong/anaconda3/lib/python3.6/site-packages/pymysql/protocol.py", line 73, in read
    raise AssertionError(error)
AssertionError: Result length not requested length:
Expected=52.  Actual=23.  Position: 20.  Data Length: 43

During handling of the above exception, another exception occurred:

Traceback (most recent call last):
  File "/home/chengtong/anaconda3/lib/python3.6/site-packages/sqlalchemy/engine/base.py", line 704, in _rollback_impl
    self.engine.dialect.do_rollback(self.connection)
  File "/home/chengtong/anaconda3/lib/python3.6/site-packages/sqlalchemy/dialects/mysql/base.py", line 1796, in do_rollback
    dbapi_connection.rollback()
  File "/home/chengtong/anaconda3/lib/python3.6/site-packages/pymysql/connections.py", line 430, in rollback
    self._read_ok_packet()
  File "/home/chengtong/anaconda3/lib/python3.6/site-packages/pymysql/connections.py", line 394, in _read_ok_packet
    pkt = self._read_packet()
  File "/home/chengtong/anaconda3/lib/python3.6/site-packages/pymysql/connections.py", line 671, in _read_packet
    % (packet_number, self._next_seq_id))
pymysql.err.InternalError: Packet sequence number wrong - got 49 expected 1

The above exception was the direct cause of the following exception:

Traceback (most recent call last):
  File "/home/chengtong/anaconda3/lib/python3.6/site-packages/sqlalchemy/engine/base.py", line 1406, in _handle_dbapi_exception
    self._autorollback()
  File "/home/chengtong/anaconda3/lib/python3.6/site-packages/sqlalchemy/util/langhelpers.py", line 76, in __exit__
    compat.reraise(type_, value, traceback)
  File "/home/chengtong/anaconda3/lib/python3.6/site-packages/sqlalchemy/util/compat.py", line 187, in reraise
    raise value
  File "/home/chengtong/anaconda3/lib/python3.6/site-packages/sqlalchemy/engine/base.py", line 1406, in _handle_dbapi_exception
    self._autorollback()
  File "/home/chengtong/anaconda3/lib/python3.6/site-packages/sqlalchemy/engine/base.py", line 827, in _autorollback
    self._root._rollback_impl()
  File "/home/chengtong/anaconda3/lib/python3.6/site-packages/sqlalchemy/engine/base.py", line 706, in _rollback_impl
    self._handle_dbapi_exception(e, None, None, None, None)
  File "/home/chengtong/anaconda3/lib/python3.6/site-packages/sqlalchemy/engine/base.py", line 1334, in _handle_dbapi_exception
    exc_info
  File "/home/chengtong/anaconda3/lib/python3.6/site-packages/sqlalchemy/util/compat.py", line 203, in raise_from_cause
    reraise(type(exception), exception, tb=exc_tb, cause=cause)
  File "/home/chengtong/anaconda3/lib/python3.6/site-packages/sqlalchemy/util/compat.py", line 186, in reraise
    raise value.with_traceback(tb)
  File "/home/chengtong/anaconda3/lib/python3.6/site-packages/sqlalchemy/engine/base.py", line 704, in _rollback_impl
    self.engine.dialect.do_rollback(self.connection)
  File "/home/chengtong/anaconda3/lib/python3.6/site-packages/sqlalchemy/dialects/mysql/base.py", line 1796, in do_rollback
    dbapi_connection.rollback()
  File "/home/chengtong/anaconda3/lib/python3.6/site-packages/pymysql/connections.py", line 430, in rollback
    self._read_ok_packet()
  File "/home/chengtong/anaconda3/lib/python3.6/site-packages/pymysql/connections.py", line 394, in _read_ok_packet
    pkt = self._read_packet()
  File "/home/chengtong/anaconda3/lib/python3.6/site-packages/pymysql/connections.py", line 671, in _read_packet
    % (packet_number, self._next_seq_id))
sqlalchemy.exc.InternalError: (pymysql.err.InternalError) Packet sequence number wrong - got 49 expected 1 (Background on this error at: http://sqlalche.me/e/2j85)

During handling of the above exception, another exception occurred:

Traceback (most recent call last):
  File "/home/chengtong/anaconda3/lib/python3.6/site-packages/sqlalchemy/pool.py", line 709, in _finalize_fairy
    fairy._reset(pool)
  File "/home/chengtong/anaconda3/lib/python3.6/site-packages/sqlalchemy/pool.py", line 880, in _reset
    pool._dialect.do_rollback(self)
  File "/home/chengtong/anaconda3/lib/python3.6/site-packages/sqlalchemy/dialects/mysql/base.py", line 1796, in do_rollback
    dbapi_connection.rollback()
  File "/home/chengtong/anaconda3/lib/python3.6/site-packages/pymysql/connections.py", line 429, in rollback
    self._execute_command(COMMAND.COM_QUERY, "ROLLBACK")
  File "/home/chengtong/anaconda3/lib/python3.6/site-packages/pymysql/connections.py", line 750, in _execute_command
    raise err.InterfaceError("(0, '')")
pymysql.err.InterfaceError: (0, '')
WARNING:root:Error Date: 2019-07-31 00:00:00
ERROR:sqlalchemy.pool.QueuePool:Exception during reset or similar
Traceback (most recent call last):
  File "/home/chengtong/anaconda3/lib/python3.6/site-packages/sqlalchemy/engine/base.py", line 1193, in _execute_context
    context)
  File "/home/chengtong/anaconda3/lib/python3.6/site-packages/sqlalchemy/engine/default.py", line 507, in do_execute
    cursor.execute(statement, parameters)
  File "/home/chengtong/anaconda3/lib/python3.6/site-packages/pymysql/cursors.py", line 170, in execute
    result = self._query(query)
  File "/home/chengtong/anaconda3/lib/python3.6/site-packages/pymysql/cursors.py", line 328, in _query
    conn.query(q)
  File "/home/chengtong/anaconda3/lib/python3.6/site-packages/pymysql/connections.py", line 517, in query
    self._affected_rows = self._read_query_result(unbuffered=unbuffered)
  File "/home/chengtong/anaconda3/lib/python3.6/site-packages/pymysql/connections.py", line 732, in _read_query_result
    result.read()
  File "/home/chengtong/anaconda3/lib/python3.6/site-packages/pymysql/connections.py", line 1082, in read
    self._read_result_packet(first_packet)
  File "/home/chengtong/anaconda3/lib/python3.6/site-packages/pymysql/connections.py", line 1152, in _read_result_packet
    self._read_rowdata_packet()
  File "/home/chengtong/anaconda3/lib/python3.6/site-packages/pymysql/connections.py", line 1190, in _read_rowdata_packet
    rows.append(self._read_row_from_packet(packet))
  File "/home/chengtong/anaconda3/lib/python3.6/site-packages/pymysql/connections.py", line 1199, in _read_row_from_packet
    data = packet.read_length_coded_string()
  File "/home/chengtong/anaconda3/lib/python3.6/site-packages/pymysql/protocol.py", line 178, in read_length_coded_string
    return self.read(length)
  File "/home/chengtong/anaconda3/lib/python3.6/site-packages/pymysql/protocol.py", line 73, in read
    raise AssertionError(error)
AssertionError: Result length not requested length:
Expected=53.  Actual=42.  Position: 1.  Data Length: 43

During handling of the above exception, another exception occurred:

Traceback (most recent call last):
  File "/home/chengtong/anaconda3/lib/python3.6/site-packages/sqlalchemy/engine/base.py", line 704, in _rollback_impl
    self.engine.dialect.do_rollback(self.connection)
  File "/home/chengtong/anaconda3/lib/python3.6/site-packages/sqlalchemy/dialects/mysql/base.py", line 1796, in do_rollback
    dbapi_connection.rollback()
  File "/home/chengtong/anaconda3/lib/python3.6/site-packages/pymysql/connections.py", line 430, in rollback
    self._read_ok_packet()
  File "/home/chengtong/anaconda3/lib/python3.6/site-packages/pymysql/connections.py", line 394, in _read_ok_packet
    pkt = self._read_packet()
  File "/home/chengtong/anaconda3/lib/python3.6/site-packages/pymysql/connections.py", line 671, in _read_packet
    % (packet_number, self._next_seq_id))
pymysql.err.InternalError: Packet sequence number wrong - got 49 expected 1

The above exception was the direct cause of the following exception:

Traceback (most recent call last):
  File "/home/chengtong/anaconda3/lib/python3.6/site-packages/sqlalchemy/engine/base.py", line 1406, in _handle_dbapi_exception
    self._autorollback()
  File "/home/chengtong/anaconda3/lib/python3.6/site-packages/sqlalchemy/util/langhelpers.py", line 76, in __exit__
    compat.reraise(type_, value, traceback)
  File "/home/chengtong/anaconda3/lib/python3.6/site-packages/sqlalchemy/util/compat.py", line 187, in reraise
    raise value
  File "/home/chengtong/anaconda3/lib/python3.6/site-packages/sqlalchemy/engine/base.py", line 1406, in _handle_dbapi_exception
    self._autorollback()
  File "/home/chengtong/anaconda3/lib/python3.6/site-packages/sqlalchemy/engine/base.py", line 827, in _autorollback
    self._root._rollback_impl()
  File "/home/chengtong/anaconda3/lib/python3.6/site-packages/sqlalchemy/engine/base.py", line 706, in _rollback_impl
    self._handle_dbapi_exception(e, None, None, None, None)
  File "/home/chengtong/anaconda3/lib/python3.6/site-packages/sqlalchemy/engine/base.py", line 1334, in _handle_dbapi_exception
    exc_info
  File "/home/chengtong/anaconda3/lib/python3.6/site-packages/sqlalchemy/util/compat.py", line 203, in raise_from_cause
    reraise(type(exception), exception, tb=exc_tb, cause=cause)
  File "/home/chengtong/anaconda3/lib/python3.6/site-packages/sqlalchemy/util/compat.py", line 186, in reraise
    raise value.with_traceback(tb)
  File "/home/chengtong/anaconda3/lib/python3.6/site-packages/sqlalchemy/engine/base.py", line 704, in _rollback_impl
    self.engine.dialect.do_rollback(self.connection)
  File "/home/chengtong/anaconda3/lib/python3.6/site-packages/sqlalchemy/dialects/mysql/base.py", line 1796, in do_rollback
    dbapi_connection.rollback()
  File "/home/chengtong/anaconda3/lib/python3.6/site-packages/pymysql/connections.py", line 430, in rollback
    self._read_ok_packet()
  File "/home/chengtong/anaconda3/lib/python3.6/site-packages/pymysql/connections.py", line 394, in _read_ok_packet
    pkt = self._read_packet()
  File "/home/chengtong/anaconda3/lib/python3.6/site-packages/pymysql/connections.py", line 671, in _read_packet
    % (packet_number, self._next_seq_id))
sqlalchemy.exc.InternalError: (pymysql.err.InternalError) Packet sequence number wrong - got 49 expected 1 (Background on this error at: http://sqlalche.me/e/2j85)

During handling of the above exception, another exception occurred:

Traceback (most recent call last):
  File "/home/chengtong/anaconda3/lib/python3.6/site-packages/sqlalchemy/pool.py", line 709, in _finalize_fairy
    fairy._reset(pool)
  File "/home/chengtong/anaconda3/lib/python3.6/site-packages/sqlalchemy/pool.py", line 880, in _reset
    pool._dialect.do_rollback(self)
  File "/home/chengtong/anaconda3/lib/python3.6/site-packages/sqlalchemy/dialects/mysql/base.py", line 1796, in do_rollback
    dbapi_connection.rollback()
  File "/home/chengtong/anaconda3/lib/python3.6/site-packages/pymysql/connections.py", line 429, in rollback
    self._execute_command(COMMAND.COM_QUERY, "ROLLBACK")
  File "/home/chengtong/anaconda3/lib/python3.6/site-packages/pymysql/connections.py", line 750, in _execute_command
    raise err.InterfaceError("(0, '')")
pymysql.err.InterfaceError: (0, '')
ERROR:root:Internal Python error in the inspect module.
Below is the traceback from this internal error.

INFO:root:
Unfortunately, your original traceback can not be constructed.

WARNING:root:Error Date: 2019-07-31 00:00:00
WARNING:root:Error Date: 2019-07-31 00:00:00
ERROR:root:Internal Python error in the inspect module.
Below is the traceback from this internal error.

INFO:root:
Unfortunately, your original traceback can not be constructed.

ERROR:sqlalchemy.pool.QueuePool:Exception during reset or similar
Traceback (most recent call last):
  File "/home/chengtong/anaconda3/lib/python3.6/site-packages/sqlalchemy/engine/base.py", line 1193, in _execute_context
    context)
  File "/home/chengtong/anaconda3/lib/python3.6/site-packages/sqlalchemy/engine/default.py", line 507, in do_execute
    cursor.execute(statement, parameters)
  File "/home/chengtong/anaconda3/lib/python3.6/site-packages/pymysql/cursors.py", line 170, in execute
    result = self._query(query)
  File "/home/chengtong/anaconda3/lib/python3.6/site-packages/pymysql/cursors.py", line 328, in _query
    conn.query(q)
  File "/home/chengtong/anaconda3/lib/python3.6/site-packages/pymysql/connections.py", line 517, in query
    self._affected_rows = self._read_query_result(unbuffered=unbuffered)
  File "/home/chengtong/anaconda3/lib/python3.6/site-packages/pymysql/connections.py", line 732, in _read_query_result
    result.read()
  File "/home/chengtong/anaconda3/lib/python3.6/site-packages/pymysql/connections.py", line 1082, in read
    self._read_result_packet(first_packet)
  File "/home/chengtong/anaconda3/lib/python3.6/site-packages/pymysql/connections.py", line 1152, in _read_result_packet
    self._read_rowdata_packet()
  File "/home/chengtong/anaconda3/lib/python3.6/site-packages/pymysql/connections.py", line 1190, in _read_rowdata_packet
    rows.append(self._read_row_from_packet(packet))
  File "/home/chengtong/anaconda3/lib/python3.6/site-packages/pymysql/connections.py", line 1199, in _read_row_from_packet
    data = packet.read_length_coded_string()
  File "/home/chengtong/anaconda3/lib/python3.6/site-packages/pymysql/protocol.py", line 178, in read_length_coded_string
    return self.read(length)
  File "/home/chengtong/anaconda3/lib/python3.6/site-packages/pymysql/protocol.py", line 73, in read
    raise AssertionError(error)
AssertionError: Result length not requested length:
Expected=48.  Actual=14.  Position: 29.  Data Length: 43

During handling of the above exception, another exception occurred:

Traceback (most recent call last):
  File "/home/chengtong/anaconda3/lib/python3.6/site-packages/sqlalchemy/engine/base.py", line 704, in _rollback_impl
    self.engine.dialect.do_rollback(self.connection)
  File "/home/chengtong/anaconda3/lib/python3.6/site-packages/sqlalchemy/dialects/mysql/base.py", line 1796, in do_rollback
    dbapi_connection.rollback()
  File "/home/chengtong/anaconda3/lib/python3.6/site-packages/pymysql/connections.py", line 430, in rollback
    self._read_ok_packet()
  File "/home/chengtong/anaconda3/lib/python3.6/site-packages/pymysql/connections.py", line 394, in _read_ok_packet
    pkt = self._read_packet()
  File "/home/chengtong/anaconda3/lib/python3.6/site-packages/pymysql/connections.py", line 671, in _read_packet
    % (packet_number, self._next_seq_id))
pymysql.err.InternalError: Packet sequence number wrong - got 49 expected 1

The above exception was the direct cause of the following exception:

Traceback (most recent call last):
  File "/home/chengtong/anaconda3/lib/python3.6/site-packages/sqlalchemy/engine/base.py", line 1406, in _handle_dbapi_exception
    self._autorollback()
  File "/home/chengtong/anaconda3/lib/python3.6/site-packages/sqlalchemy/util/langhelpers.py", line 76, in __exit__
    compat.reraise(type_, value, traceback)
  File "/home/chengtong/anaconda3/lib/python3.6/site-packages/sqlalchemy/util/compat.py", line 187, in reraise
    raise value
  File "/home/chengtong/anaconda3/lib/python3.6/site-packages/sqlalchemy/engine/base.py", line 1406, in _handle_dbapi_exception
    self._autorollback()
  File "/home/chengtong/anaconda3/lib/python3.6/site-packages/sqlalchemy/engine/base.py", line 827, in _autorollback
    self._root._rollback_impl()
  File "/home/chengtong/anaconda3/lib/python3.6/site-packages/sqlalchemy/engine/base.py", line 706, in _rollback_impl
    self._handle_dbapi_exception(e, None, None, None, None)
  File "/home/chengtong/anaconda3/lib/python3.6/site-packages/sqlalchemy/engine/base.py", line 1334, in _handle_dbapi_exception
    exc_info
  File "/home/chengtong/anaconda3/lib/python3.6/site-packages/sqlalchemy/util/compat.py", line 203, in raise_from_cause
    reraise(type(exception), exception, tb=exc_tb, cause=cause)
  File "/home/chengtong/anaconda3/lib/python3.6/site-packages/sqlalchemy/util/compat.py", line 186, in reraise
    raise value.with_traceback(tb)
  File "/home/chengtong/anaconda3/lib/python3.6/site-packages/sqlalchemy/engine/base.py", line 704, in _rollback_impl
    self.engine.dialect.do_rollback(self.connection)
  File "/home/chengtong/anaconda3/lib/python3.6/site-packages/sqlalchemy/dialects/mysql/base.py", line 1796, in do_rollback
    dbapi_connection.rollback()
  File "/home/chengtong/anaconda3/lib/python3.6/site-packages/pymysql/connections.py", line 430, in rollback
    self._read_ok_packet()
  File "/home/chengtong/anaconda3/lib/python3.6/site-packages/pymysql/connections.py", line 394, in _read_ok_packet
    pkt = self._read_packet()
  File "/home/chengtong/anaconda3/lib/python3.6/site-packages/pymysql/connections.py", line 671, in _read_packet
    % (packet_number, self._next_seq_id))
sqlalchemy.exc.InternalError: (pymysql.err.InternalError) Packet sequence number wrong - got 49 expected 1 (Background on this error at: http://sqlalche.me/e/2j85)

During handling of the above exception, another exception occurred:

Traceback (most recent call last):
  File "/home/chengtong/anaconda3/lib/python3.6/site-packages/sqlalchemy/pool.py", line 709, in _finalize_fairy
    fairy._reset(pool)
  File "/home/chengtong/anaconda3/lib/python3.6/site-packages/sqlalchemy/pool.py", line 880, in _reset
    pool._dialect.do_rollback(self)
  File "/home/chengtong/anaconda3/lib/python3.6/site-packages/sqlalchemy/dialects/mysql/base.py", line 1796, in do_rollback
    dbapi_connection.rollback()
  File "/home/chengtong/anaconda3/lib/python3.6/site-packages/pymysql/connections.py", line 429, in rollback
    self._execute_command(COMMAND.COM_QUERY, "ROLLBACK")
  File "/home/chengtong/anaconda3/lib/python3.6/site-packages/pymysql/connections.py", line 750, in _execute_command
    raise err.InterfaceError("(0, '')")
pymysql.err.InterfaceError: (0, '')
ERROR:root:Internal Python error in the inspect module.
Below is the traceback from this internal error.

INFO:root:
Unfortunately, your original traceback can not be constructed.

ERROR:root:Internal Python error in the inspect module.
Below is the traceback from this internal error.

INFO:root:
Unfortunately, your original traceback can not be constructed.

ERROR:root:Internal Python error in the inspect module.
Below is the traceback from this internal error.

INFO:root:
Unfortunately, your original traceback can not be constructed.

